Workbook

Sheet Tablica
A1: Oznaka lukovice | B1: Faze | I1: Mutacije | P1: Ostalo
B2: Interfaza | C2: Profaza | D2: Metafaza | E2: Anafaza | F2: Telofaza | G2: Ukupno stanica | H2: Mitotski indeks | I2: Anafazni mostovi | J2: Lomovi kromosoma | K2: C-mitoza | L2: Ljepljivi kromosoma | M2: Ostale mutacije | N2: Ukupno mutacija | O2: Udio mutacija | P2: Mikronukelusi | Q2: Udio mikronukleusa | R2: Interfazne vakuole | S2: Udio interfaznih vakuola
A3: K- a | B3: 377 | C3: 182 | D3: 3 | E3: 0 | F3: 1 | G3: =SUM(B3:F3) -> 563 | H3: =IFERROR(SUM(C3:F3)/G3,0) -> 0.330373 | I3: 0 | J3: 0 | K3: 0 | L3: 0 | M3: 0 | N3: =SUM(I3:M3) -> 0 | O3: =IFERROR(N3/G3,0) -> 0 | Q3: =IFERROR(P3/G3,0) -> 0 | R3: 40 | S3: =IFERROR(R3/G3,0) -> 0.071047957
A4: K- b | B4: 472 | C4: 156 | D4: 5 | E4: 1 | F4: 0 | G4: =SUM(B4:F4) -> 634 | H4: =IFERROR(SUM(C4:F4)/G4,0) -> 0.2555205 | I4: 1 | J4: 0 | K4: 0 | L4: 0 | M4: 0 | N4: =SUM(I4:M4) -> 1 | O4: =IFERROR(N4/G4,0) -> 0.0015772871 | Q4: =IFERROR(P4/G4,0) -> 0 | R4: 46 | S4: =IFERROR(R4/G4,0) -> 0.072555205
A5: K- c | B5: 368 | C5: 155 | D5: 3 | E5: 0 | F5: 0 | G5: =SUM(B5:F5) -> 526 | H5: =IFERROR(SUM(C5:F5)/G5,0) -> 0.30038023 | I5: 0 | J5: 0 | K5: 0 | L5: 1 | M5: 0 | N5: =SUM(I5:M5) -> 1 | O5: =IFERROR(N5/G5,0) -> 0.0019011407 | Q5: =IFERROR(P5/G5,0) -> 0 | R5: 36 | S5: =IFERROR(R5/G5,0) -> 0.068441065
A6: K- d | B6: 336 | C6: 215 | D6: 0 | E6: 1 | F6: 1 | G6: =SUM(B6:F6) -> 553 | H6: =IFERROR(SUM(C6:F6)/G6,0) -> 0.39240506 | I6: 0 | J6: 0 | K6: 0 | L6: 0 | M6: 0 | N6: =SUM(I6:M6) -> 0 | O6: =IFERROR(N6/G6,0) -> 0 | Q6: =IFERROR(P6/G6,0) -> 0 | R6: 32 | S6: =IFERROR(R6/G6,0) -> 0.057866184
A7: K- e | B7: 289 | C7: 130 | D7: 2 | E7: 0 | F7: 1 | G7: =SUM(B7:F7) -> 422 | H7: =IFERROR(SUM(C7:F7)/G7,0) -> 0.31516588 | I7: 0 | J7: 0 | K7: 0 | L7: 0 | M7: 0 | N7: =SUM(I7:M7) -> 0 | O7: =IFERROR(N7/G7,0) -> 0 | Q7: =IFERROR(P7/G7,0) -> 0 | R7: 18 | S7: =IFERROR(R7/G7,0) -> 0.042654028
A8: K- | B8: =SUM(B3:B7) -> 1842 | C8: =SUM(C3:C7) -> 838 | D8: =SUM(D3:D7) -> 13 | E8: =SUM(E3:E7) -> 2 | F8: =SUM(F3:F7) -> 3 | G8: =SUM(B8:F8) -> 2698 | H8: =IFERROR(SUM(C8:F8)/G8,0) -> 0.31727205 | I8: =SUM(I3:I7) -> 1 | J8: =SUM(J3:J7) -> 0 | K8: =SUM(K3:K7) -> 0 | L8: =SUM(L3:L7) -> 1 | M8: =SUM(M3:M7) -> 0 | N8: =SUM(I8:M8) -> 2 | O8: =IFERROR(N8/G8,0) -> 0.00074128984 | P8: =SUM(P3:P7) -> 0 | Q8: =IFERROR(P8/G8,0) -> 0 | R8: =SUM(R3:R7) -> 172 | S8: =IFERROR(R8/G8,0) -> 0.063750927
A9: K+ a | B9: 430 | C9: 64 | D9: 2 | E9: 2 | F9: 2 | G9: =SUM(B9:F9) -> 500 | H9: =IFERROR(SUM(C9:F9)/G9,0) -> 0.14 | I9: 1 | J9: 0 | K9: 0 | L9: 0 | M9: 0 | N9: =SUM(I9:M9) -> 1 | O9: =IFERROR(N9/G9,0) -> 0.002 | Q9: =IFERROR(P9/G9,0) -> 0 | R9: 47 | S9: =IFERROR(R9/G9,0) -> 0.094
A10: K+ b | B10: 200 | C10: 300 | D10: 0 | E10: 0 | F10: 1 | G10: =SUM(B10:F10) -> 501 | H10: =IFERROR(SUM(C10:F10)/G10,0) -> 0.6007984 | I10: 0 | J10: 0 | K10: 4 | L10: 0 | M10: 0 | N10: =SUM(I10:M10) -> 4 | O10: =IFERROR(N10/G10,0) -> 0.0079840319 | Q10: =IFERROR(P10/G10,0) -> 0 | R10: 27 | S10: =IFERROR(R10/G10,0) -> 0.053892216
A11: K+ c | B11: 124 | C11: 124 | D11: 0 | E11: 0 | F11: 0 | G11: =SUM(B11:F11) -> 248 | H11: =IFERROR(SUM(C11:F11)/G11,0) -> 0.5 | I11: 0 | J11: 0 | K11: 1 | L11: 0 | M11: 0 | N11: =SUM(I11:M11) -> 1 | O11: =IFERROR(N11/G11,0) -> 0.0040322581 | Q11: =IFERROR(P11/G11,0) -> 0 | R11: 40 | S11: =IFERROR(R11/G11,0) -> 0.16129032
A12: K+ d | B12: 25 | C12: 102 | D12: 0 | E12: 0 | F12: 0 | G12: =SUM(B12:F12) -> 127 | H12: =IFERROR(SUM(C12:F12)/G12,0) -> 0.80314961 | I12: 0 | J12: 0 | K12: 0 | L12: 0 | M12: 0 | N12: =SUM(I12:M12) -> 0 | O12: =IFERROR(N12/G12,0) -> 0 | Q12: =IFERROR(P12/G12,0) -> 0 | R12: 14 | S12: =IFERROR(R12/G12,0) -> 0.11023622
A13: K+ e | G13: =SUM(B13:F13) -> 0 | H13: =IFERROR(SUM(C13:F13)/G13,0) -> 0 | N13: =SUM(I13:M13) -> 0 | O13: =IFERROR(N13/G13,0) -> 0 | Q13: =IFERROR(P13/G13,0) -> 0 | S13: =IFERROR(R13/G13,0) -> 0
A14: K+ | B14: =SUM(B9:B13) -> 779 | C14: =SUM(C9:C13) -> 590 | D14: =SUM(D9:D13) -> 2 | E14: =SUM(E9:E13) -> 2 | F14: =SUM(F9:F13) -> 3 | G14: =SUM(B14:F14) -> 1376 | H14: =IFERROR(SUM(C14:F14)/G14,0) -> 0.43386628 | I14: =SUM(I9:I13) -> 1 | J14: =SUM(J9:J13) -> 0 | K14: =SUM(K9:K13) -> 5 | L14: =SUM(L9:L13) -> 0 | M14: =SUM(M9:M13) -> 0 | N14: =SUM(I14:M14) -> 6 | O14: =IFERROR(N14/G14,0) -> 0.0043604651 | P14: =SUM(P9:P13) -> 0 | Q14: =IFERROR(P14/G14,0) -> 0 | R14: =SUM(R9:R13) -> 128 | S14: =IFERROR(R14/G14,0) -> 0.093023256
A15: V1 a | B15: 288 | C15: 118 | D15: 0 | E15: 0 | F15: 0 | G15: =SUM(B15:F15) -> 406 | H15: =IFERROR(SUM(C15:F15)/G15,0) -> 0.29064039 | I15: 0 | J15: 0 | K15: 0 | L15: 0 | M15: 0 | N15: =SUM(I15:M15) -> 0 | O15: =IFERROR(N15/G15,0) -> 0 | Q15: =IFERROR(P15/G15,0) -> 0 | R15: 57 | S15: =IFERROR(R15/G15,0) -> 0.14039409
A16: V1 b | B16: 157 | C16: 288 | D16: 0 | E16: 0 | F16: 0 | G16: =SUM(B16:F16) -> 445 | H16: =IFERROR(SUM(C16:F16)/G16,0) -> 0.64719101 | I16: 0 | J16: 0 | K16: 0 | L16: 0 | M16: 0 | N16: =SUM(I16:M16) -> 0 | O16: =IFERROR(N16/G16,0) -> 0 | Q16: =IFERROR(P16/G16,0) -> 0 | R16: 0 | S16: =IFERROR(R16/G16,0) -> 0
A17: V1 c | B17: 187 | C17: 320 | D17: 0 | E17: 0 | F17: 0 | G17: =SUM(B17:F17) -> 507 | H17: =IFERROR(SUM(C17:F17)/G17,0) -> 0.63116371 | I17: 0 | J17: 0 | K17: 0 | L17: 0 | M17: 0 | N17: =SUM(I17:M17) -> 0 | O17: =IFERROR(N17/G17,0) -> 0 | Q17: =IFERROR(P17/G17,0) -> 0 | R17: 8 | S17: =IFERROR(R17/G17,0) -> 0.015779093
A18: V1 d | B18: 239 | C18: 237 | D18: 0 | E18: 0 | F18: 0 | G18: =SUM(B18:F18) -> 476 | H18: =IFERROR(SUM(C18:F18)/G18,0) -> 0.49789916 | I18: 0 | J18: 0 | K18: 0 | L18: 0 | M18: 0 | N18: =SUM(I18:M18) -> 0 | O18: =IFERROR(N18/G18,0) -> 0 | Q18: =IFERROR(P18/G18,0) -> 0 | R18: 65 | S18: =IFERROR(R18/G18,0) -> 0.13655462
A19: V1 e | B19: 290 | C19: 295 | D19: 4 | E19: 9 | F19: 2 | G19: =SUM(B19:F19) -> 600 | H19: =IFERROR(SUM(C19:F19)/G19,0) -> 0.51666667 | I19: 1 | J19: 2 | K19: 0 | L19: 1 | M19: 0 | N19: =SUM(I19:M19) -> 4 | O19: =IFERROR(N19/G19,0) -> 0.0066666667 | Q19: =IFERROR(P19/G19,0) -> 0 | R19: 123 | S19: =IFERROR(R19/G19,0) -> 0.205
A20: V1 | B20: =SUM(B15:B19) -> 1161 | C20: =SUM(C15:C19) -> 1258 | D20: =SUM(D15:D19) -> 4 | E20: =SUM(E15:E19) -> 9 | F20: =SUM(F15:F19) -> 2 | G20: =SUM(B20:F20) -> 2434 | H20: =IFERROR(SUM(C20:F20)/G20,0) -> 0.5230074 | I20: =SUM(I15:I19) -> 1 | J20: =SUM(J15:J19) -> 2 | K20: =SUM(K15:K19) -> 0 | L20: =SUM(L15:L19) -> 1 | M20: =SUM(M15:M19) -> 0 | N20: =SUM(I20:M20) -> 4 | O20: =IFERROR(N20/G20,0) -> 0.0016433854 | P20: =SUM(P15:P19) -> 0 | Q20: =IFERROR(P20/G20,0) -> 0 | R20: =SUM(R15:R19) -> 253 | S20: =IFERROR(R20/G20,0) -> 0.10394412
A21: A1 a | B21: 789 | C21: 673 | D21: 1 | E21: 1 | F21: 0 | G21: =SUM(B21:F21) -> 1464 | H21: =IFERROR(SUM(C21:F21)/G21,0) -> 0.46106557 | I21: 0 | J21: 0 | K21: 0 | L21: 0 | M21: 0 | N21: =SUM(I21:M21) -> 0 | O21: =IFERROR(N21/G21,0) -> 0 | Q21: =IFERROR(P21/G21,0) -> 0 | R21: 500 | S21: =IFERROR(R21/G21,0) -> 0.34153005
A22: A1 b | B22: 386 | C22: 680 | D22: 12 | E22: 5 | F22: 8 | G22: =SUM(B22:F22) -> 1091 | H22: =IFERROR(SUM(C22:F22)/G22,0) -> 0.64619615 | I22: 1 | J22: 0 | K22: 0 | L22: 2 | M22: 0 | N22: =SUM(I22:M22) -> 3 | O22: =IFERROR(N22/G22,0) -> 0.0027497709 | Q22: =IFERROR(P22/G22,0) -> 0 | R22: 217 | S22: =IFERROR(R22/G22,0) -> 0.19890009
A23: A1 c | B23: 286 | C23: 361 | D23: 4 | E23: 0 | F23: 1 | G23: =SUM(B23:F23) -> 652 | H23: =IFERROR(SUM(C23:F23)/G23,0) -> 0.56134969 | I23: 0 | J23: 0 | K23: 0 | L23: 1 | M23: 0 | N23: =SUM(I23:M23) -> 1 | O23: =IFERROR(N23/G23,0) -> 0.0015337423 | Q23: =IFERROR(P23/G23,0) -> 0 | R23: 120 | S23: =IFERROR(R23/G23,0) -> 0.18404908
A24: A1 d | B24: 228 | C24: 279 | D24: 3 | E24: 2 | F24: 1 | G24: =SUM(B24:F24) -> 513 | H24: =IFERROR(SUM(C24:F24)/G24,0) -> 0.55555556 | I24: 0 | J24: 0 | K24: 0 | L24: 0 | M24: 0 | N24: =SUM(I24:M24) -> 0 | O24: =IFERROR(N24/G24,0) -> 0 | Q24: =IFERROR(P24/G24,0) -> 0 | R24: 6 | S24: =IFERROR(R24/G24,0) -> 0.011695906
A25: A1 e | B25: 362 | C25: 290 | D25: 0 | E25: 0 | F25: 2 | G25: =SUM(B25:F25) -> 654 | H25: =IFERROR(SUM(C25:F25)/G25,0) -> 0.44648318 | I25: 0 | J25: 0 | K25: 0 | L25: 0 | M25: 0 | N25: =SUM(I25:M25) -> 0 | O25: =IFERROR(N25/G25,0) -> 0 | Q25: =IFERROR(P25/G25,0) -> 0 | R25: 310 | S25: =IFERROR(R25/G25,0) -> 0.47400612
A26: A1 | B26: =SUM(B21:B25) -> 2051 | C26: =SUM(C21:C25) -> 2283 | D26: =SUM(D21:D25) -> 20 | E26: =SUM(E21:E25) -> 8 | F26: =SUM(F21:F25) -> 12 | G26: =SUM(B26:F26) -> 4374 | H26: =IFERROR(SUM(C26:F26)/G26,0) -> 0.53109282 | I26: =SUM(I21:I25) -> 1 | J26: =SUM(J21:J25) -> 0 | K26: =SUM(K21:K25) -> 0 | L26: =SUM(L21:L25) -> 3 | M26: =SUM(M21:M25) -> 0 | N26: =SUM(I26:M26) -> 4 | O26: =IFERROR(N26/G26,0) -> 0.00091449474 | P26: =SUM(P21:P25) -> 0 | Q26: =IFERROR(P26/G26,0) -> 0 | R26: =SUM(R21:R25) -> 1153 | S26: =IFERROR(R26/G26,0) -> 0.26360311
A27: U1 a | B27: 312 | C27: 252 | D27: 2 | E27: 0 | F27: 2 | G27: =SUM(B27:F27) -> 568 | H27: =IFERROR(SUM(C27:F27)/G27,0) -> 0.45070423 | I27: 0 | J27: 0 | K27: 1 | L27: 0 | M27: 0 | N27: =SUM(I27:M27) -> 1 | O27: =IFERROR(N27/G27,0) -> 0.0017605634 | Q27: =IFERROR(P27/G27,0) -> 0 | R27: 136 | S27: =IFERROR(R27/G27,0) -> 0.23943662
A28: U1 b | B28: 197 | C28: 237 | D28: 6 | E28: 1 | F28: 1 | G28: =SUM(B28:F28) -> 442 | H28: =IFERROR(SUM(C28:F28)/G28,0) -> 0.55429864 | I28: 0 | J28: 0 | K28: 2 | L28: 0 | N28: =SUM(I28:M28) -> 2 | O28: =IFERROR(N28/G28,0) -> 0.0045248869 | Q28: =IFERROR(P28/G28,0) -> 0 | R28: 14 | S28: =IFERROR(R28/G28,0) -> 0.031674208
A29: U1 c | B29: 274 | C29: 273 | D29: 2 | E29: 0 | F29: 1 | G29: =SUM(B29:F29) -> 550 | H29: =IFERROR(SUM(C29:F29)/G29,0) -> 0.50181818 | I29: 0 | J29: 0 | K29: 0 | L29: 0 | M29: 0 | N29: =SUM(I29:M29) -> 0 | O29: =IFERROR(N29/G29,0) -> 0 | Q29: =IFERROR(P29/G29,0) -> 0 | R29: 56 | S29: =IFERROR(R29/G29,0) -> 0.10181818
A30: U1 d | G30: =SUM(B30:F30) -> 0 | H30: =IFERROR(SUM(C30:F30)/G30,0) -> 0 | I30: 0 | J30: 0 | K30: 0 | L30: 0 | M30: 0 | N30: =SUM(I30:M30) -> 0 | O30: =IFERROR(N30/G30,0) -> 0 | Q30: =IFERROR(P30/G30,0) -> 0 | S30: =IFERROR(R30/G30,0) -> 0
A31: U1 e | B31: 268 | C31: 216 | D31: 5 | E31: 2 | F31: 2 | G31: =SUM(B31:F31) -> 493 | H31: =IFERROR(SUM(C31:F31)/G31,0) -> 0.45638945 | I31: 1 | J31: 1 | K31: 4 | L31: 1 | M31: 0 | N31: =SUM(I31:M31) -> 7 | O31: =IFERROR(N31/G31,0) -> 0.014198783 | Q31: =IFERROR(P31/G31,0) -> 0 | R31: 56 | S31: =IFERROR(R31/G31,0) -> 0.11359026
A32: U1 | B32: =SUM(B27:B31) -> 1051 | C32: =SUM(C27:C31) -> 978 | D32: =SUM(D27:D31) -> 15 | E32: =SUM(E27:E31) -> 3 | F32: =SUM(F27:F31) -> 6 | G32: =SUM(B32:F32) -> 2053 | H32: =IFERROR(SUM(C32:F32)/G32,0) -> 0.48806624 | I32: =SUM(I27:I31) -> 1 | J32: =SUM(J27:J31) -> 1 | K32: =SUM(K27:K31) -> 7 | L32: =SUM(L27:L31) -> 1 | M32: =SUM(M27:M31) -> 0 | N32: =SUM(I32:M32) -> 10 | O32: =IFERROR(N32/G32,0) -> 0.0048709206 | P32: =SUM(P27:P31) -> 0 | Q32: =IFERROR(P32/G32,0) -> 0 | R32: =SUM(R27:R31) -> 262 | S32: =IFERROR(R32/G32,0) -> 0.12761812
A33: V2 a | B33: 226 | C33: 357 | D33: 2 | E33: 2 | F33: 0 | G33: =SUM(B33:F33) -> 587 | H33: =IFERROR(SUM(C33:F33)/G33,0) -> 0.61499148 | I33: 1 | J33: 0 | K33: 1 | L33: 1 | M33: 0 | N33: =SUM(I33:M33) -> 3 | O33: =IFERROR(N33/G33,0) -> 0.0051107325 | Q33: =IFERROR(P33/G33,0) -> 0 | R33: 20 | S33: =IFERROR(R33/G33,0) -> 0.03407155
A34: V2 b | B34: 183 | C34: 192 | D34: 1 | E34: 1 | F34: 0 | G34: =SUM(B34:F34) -> 377 | H34: =IFERROR(SUM(C34:F34)/G34,0) -> 0.51458886 | I34: 0 | J34: 0 | K34: 1 | L34: 0 | M34: 0 | N34: =SUM(I34:M34) -> 1 | O34: =IFERROR(N34/G34,0) -> 0.0026525199 | Q34: =IFERROR(P34/G34,0) -> 0 | R34: 63 | S34: =IFERROR(R34/G34,0) -> 0.16710875
A35: V2 c | B35: 257 | C35: 346 | D35: 0 | E35: 0 | F35: 1 | G35: =SUM(B35:F35) -> 604 | H35: =IFERROR(SUM(C35:F35)/G35,0) -> 0.57450331 | I35: 0 | J35: 0 | K35: 0 | L35: 0 | M35: 0 | N35: =SUM(I35:M35) -> 0 | O35: =IFERROR(N35/G35,0) -> 0 | Q35: =IFERROR(P35/G35,0) -> 0 | R35: 54 | S35: =IFERROR(R35/G35,0) -> 0.089403974
A36: V2 d | B36: 224 | C36: 321 | D36: 0 | E36: 0 | F36: 0 | G36: =SUM(B36:F36) -> 545 | H36: =IFERROR(SUM(C36:F36)/G36,0) -> 0.58899083 | I36: 0 | J36: 0 | K36: 0 | L36: 0 | M36: 0 | N36: =SUM(I36:M36) -> 0 | O36: =IFERROR(N36/G36,0) -> 0 | Q36: =IFERROR(P36/G36,0) -> 0 | R36: 47 | S36: =IFERROR(R36/G36,0) -> 0.086238532
A37: V2 e | B37: 176 | C37: 250 | D37: 3 | E37: 0 | F37: 0 | G37: =SUM(B37:F37) -> 429 | H37: =IFERROR(SUM(C37:F37)/G37,0) -> 0.58974359 | I37: 0 | J37: 0 | K37: 3 | L37: 2 | M37: 0 | N37: =SUM(I37:M37) -> 5 | O37: =IFERROR(N37/G37,0) -> 0.011655012 | Q37: =IFERROR(P37/G37,0) -> 0 | R37: 73 | S37: =IFERROR(R37/G37,0) -> 0.17016317
A38: V2 | B38: =SUM(B33:B37) -> 1066 | C38: =SUM(C33:C37) -> 1466 | D38: =SUM(D33:D37) -> 6 | E38: =SUM(E33:E37) -> 3 | F38: =SUM(F33:F37) -> 1 | G38: =SUM(B38:F38) -> 2542 | H38: =IFERROR(SUM(C38:F38)/G38,0) -> 0.58064516 | I38: =SUM(I33:I37) -> 1 | J38: =SUM(J33:J37) -> 0 | K38: =SUM(K33:K37) -> 5 | L38: =SUM(L33:L37) -> 3 | M38: =SUM(M33:M37) -> 0 | N38: =SUM(I38:M38) -> 9 | O38: =IFERROR(N38/G38,0) -> 0.0035405193 | P38: =SUM(P33:P37) -> 0 | Q38: =IFERROR(P38/G38,0) -> 0 | R38: =SUM(R33:R37) -> 257 | S38: =IFERROR(R38/G38,0) -> 0.10110149
A39: A2 a | B39: 324 | C39: 178 | D39: 1 | E39: 0 | F39: 5 | G39: =SUM(B39:F39) -> 508 | H39: =IFERROR(SUM(C39:F39)/G39,0) -> 0.36220472 | I39: 0 | J39: 0 | K39: 0 | L39: 0 | M39: 0 | N39: =SUM(I39:M39) -> 0 | O39: =IFERROR(N39/G39,0) -> 0 | Q39: =IFERROR(P39/G39,0) -> 0 | R39: 149 | S39: =IFERROR(R39/G39,0) -> 0.29330709
A40: A2 b | B40: 104 | C40: 183 | D40: 0 | E40: 0 | F40: 0 | G40: =SUM(B40:F40) -> 287 | H40: =IFERROR(SUM(C40:F40)/G40,0) -> 0.63763066 | I40: 0 | J40: 0 | K40: 0 | L40: 0 | M40: 0 | N40: =SUM(I40:M40) -> 0 | O40: =IFERROR(N40/G40,0) -> 0 | Q40: =IFERROR(P40/G40,0) -> 0 | R40: 36 | S40: =IFERROR(R40/G40,0) -> 0.12543554
...

Sheet Mitotski indeks
A1: K- | B1: K+ | C1: V1 | D1: A1 | E1: U1 | F1: V2 | G1: A2 | H1: U2 | J1: K- | K1: K+ | L1: V1 | M1: A1 | N1: U1 | O1: V2 | P1: A2 | Q1: U2
A2: =SUM(Tablica!C3:F3)/Tablica!G3 -> 0.330373 | B2: =SUM(Tablica!C9:F9)/Tablica!G9 -> 0.14 | C2: =SUM(Tablica!C15:F15)/Tablica!G15 -> 0.29064039 | D2: =SUM(Tablica!C21:F21)/Tablica!G21 -> 0.46106557 | E2: =SUM(Tablica!C27:F27)/Tablica!G27 -> 0.45070423 | F2: =SUM(Tablica!C33:F33)/Tablica!G33 -> 0.61499148 | G2: =SUM(Tablica!C39:F39)/Tablica!G39 -> 0.36220472 | H2: =SUM(Tablica!C45:F45)/Tablica!G45 -> 0.50097466 | J2: =_xlfn.STDEV.S(A2:A6)*100 -> 4.9770534 | K2: =_xlfn.STDEV.S(B2:B6)*100 -> 27.759512 | L2: =_xlfn.STDEV.S(C2:C6)*100 -> 14.281654 | M2: =_xlfn.STDEV.S(D2:D6)*100 -> 8.1821702 | N2: =_xlfn.STDEV.S(E2:E6)*100 -> 4.811526 | O2: =_xlfn.STDEV.S(F2:F6)*100 -> 3.7583119 | P2: =_xlfn.STDEV.S(G2:G6)*100 -> 10.867283 | Q2: =_xlfn.STDEV.S(H2:H6)*100 -> 13.461606
A3: =SUM(Tablica!C4:F4)/Tablica!G4 -> 0.2555205 | B3: =SUM(Tablica!C10:F10)/Tablica!G10 -> 0.6007984 | C3: =SUM(Tablica!C16:F16)/Tablica!G16 -> 0.64719101 | D3: =SUM(Tablica!C22:F22)/Tablica!G22 -> 0.64619615 | E3: =SUM(Tablica!C28:F28)/Tablica!G28 -> 0.55429864 | F3: =SUM(Tablica!C34:F34)/Tablica!G34 -> 0.51458886 | G3: =SUM(Tablica!C40:F40)/Tablica!G40 -> 0.63763066 | H3: =SUM(Tablica!C46:F46)/Tablica!G46 -> 0.60658579
A4: =SUM(Tablica!C5:F5)/Tablica!G5 -> 0.30038023 | B4: =SUM(Tablica!C11:F11)/Tablica!G11 -> 0.5 | C4: =SUM(Tablica!C17:F17)/Tablica!G17 -> 0.63116371 | D4: =SUM(Tablica!C23:F23)/Tablica!G23 -> 0.56134969 | E4: =SUM(Tablica!C29:F29)/Tablica!G29 -> 0.50181818 | F4: =SUM(Tablica!C35:F35)/Tablica!G35 -> 0.57450331 | G4: =SUM(Tablica!C41:F41)/Tablica!G41 -> 0.44 | H4: =SUM(Tablica!C47:F47)/Tablica!G47 -> 0.43614931
A5: =SUM(Tablica!C6:F6)/Tablica!G6 -> 0.39240506 | B5: =SUM(Tablica!C12:F12)/Tablica!G12 -> 0.80314961 | C5: =SUM(Tablica!C18:F18)/Tablica!G18 -> 0.49789916 | D5: =SUM(Tablica!C24:F24)/Tablica!G24 -> 0.55555556 | F5: =SUM(Tablica!C36:F36)/Tablica!G36 -> 0.58899083 | G5: =SUM(Tablica!C42:F42)/Tablica!G42 -> 0.38931298 | H5: =SUM(Tablica!C48:F48)/Tablica!G48 -> 0.52371542
A6: =SUM(Tablica!C7:F7)/Tablica!G7 -> 0.31516588 | C6: =SUM(Tablica!C19:F19)/Tablica!G19 -> 0.51666667 | D6: =SUM(Tablica!C25:F25)/Tablica!G25 -> 0.44648318 | E6: =SUM(Tablica!C31:F31)/Tablica!G31 -> 0.45638945 | F6: =SUM(Tablica!C37:F37)/Tablica!G37 -> 0.58974359 | G6: =SUM(Tablica!C43:F43)/Tablica!G43 -> 0.42655936 | H6: =SUM(Tablica!C49:F49)/Tablica!G49 -> 0.7852349
A8: Anova: Single Factor
A10: SUMMARY
A11: Groups | B11: Count | C11: Sum | D11: Average | E11: Variance
A12: Column 1 | B12: 5 | C12: 1.5938447 | D12: 0.31876893 | E12: 0.0024771061
A13: Column 2 | B13: 4 | C13: 2.043948 | D13: 0.510987 | E13: 0.077059048
A14: Column 3 | B14: 5 | C14: 2.5835609 | D14: 0.51671219 | E14: 0.020396565
A15: Column 4 | B15: 5 | C15: 2.6706502 | D15: 0.53413003 | E15: 0.0066947909
A16: Column 5 | B16: 4 | C16: 1.9632105 | D16: 0.49080263 | E16: 0.0023150783
A17: Column 6 | B17: 5 | C17: 2.8828181 | D17: 0.57656361 | E17: 0.0014124909
A18: Column 7 | B18: 5 | C18: 2.2557077 | D18: 0.45114154 | E18: 0.011809785
A19: Column 8 | B19: 5 | C19: 2.8526601 | D19: 0.57053201 | E19: 0.018121483
A22: ANOVA
A23: Source of Variation | B23: SS | C23: df | D23: MS | E23: F | F23: P-value | G23: F crit
A24: Between Groups | B24: 0.23776414 | C24: 7 | D24: 0.033966305 | E24: 2.1150891 | F24: 0.072589752 | G24: 2.334344
A25: Within Groups | B25: 0.48177127 | C25: 30 | D25: 0.016059042
A27: Total | B27: 0.7195354 | C27: 37
A30: Group1 | B30: Group2 | C30: Statistic | D30: PValue | E30: CI_Low | F30: CI_High
A31: K- | B31: K+ | C31: -0.192218 | D31: 0.346585 | E31: -0.468812 | F31: 0.084376
A32: K- | B32: V1 | C32: -0.197943 | D32: 0.24653 | E32: -0.458718 | F32: 0.062832
A33: K- | B33: A1 | C33: -0.215361 | D33: 0.165762 | E33: -0.476136 | F33: 0.045414
A34: K- | B34: U1 | C34: -0.172034 | D34: 0.483763 | E34: -0.448628 | F34: 0.10456
A35: K- | B35: V2 | C35: -0.257795 | D35: 0.054421 | E35: -0.51857 | F35: 0.00298
A36: K- | B36: A2 | C36: -0.132373 | D36: 0.716401 | E36: -0.393148 | F36: 0.128403
A37: K- | B37: U2 | C37: -0.251763 | D37: 0.06445 | E37: -0.512538 | F37: 0.009012
A38: K+ | B38: V1 | C38: -0.005725 | D38: 1 | E38: -0.282319 | F38: 0.270869
A39: K+ | B39: A1 | C39: -0.023143 | D39: 0.999993 | E39: -0.299737 | F39: 0.253451
A40: K+ | B40: U1 | C40: 0.020184 | D40: 0.999998 | E40: -0.271371 | F40: 0.31174
A41: K+ | B41: V2 | C41: -0.065577 | D41: 0.993425 | E41: -0.34217 | F41: 0.211017
A42: K+ | B42: A2 | C42: 0.059845 | D42: 0.996232 | E42: -0.216748 | F42: 0.336439
... A58: A2 | B58: U2 | C58: -0.11939 | D58: 0.806765 | E58: -0.380166 | F58: 0.141385

Sheet Mutacije
A1: K- | B1: K+ | C1: V1 | D1: A1 | E1: U1 | F1: V2 | G1: A2 | H1: U2 | J1: K- | K1: K+ | L1: V1 | M1: A1 | N1: U1 | O1: V2 | P1: A2 | Q1: U2
A2: =Tablica!N3/Tablica!G3 -> 0 | B2: =Tablica!N9/Tablica!G9 -> 0.002 | C2: =Tablica!N15/Tablica!G15 -> 0 | D2: =Tablica!N21/Tablica!G21 -> 0 | E2: =Tablica!N27/Tablica!G27 -> 0.0017605634 | F2: =Tablica!N33/Tablica!G33 -> 0.0051107325 | G2: =Tablica!N39/Tablica!G39 -> 0 | H2: =Tablica!N45/Tablica!G45 -> 0.0038986355 | J2: =_xlfn.STDEV.S(A2:A6)*100 -> 0.095946319 | K2: =_xlfn.STDEV.S(B2:B6)*100 -> 0.34102676 | L2: =_xlfn.STDEV.S(C2:C6)*100 -> 0.2981424 | M2: =_xlfn.STDEV.S(D2:D6)*100 -> 0.12493907 | N2: =_xlfn.STDEV.S(E2:E6)*100 -> 0.63318947 | O2: =_xlfn.STDEV.S(F2:F6)*100 -> 0.48368623 | P2: =_xlfn.STDEV.S(G2:G6)*100 -> 0.085346106 | Q2: =_xlfn.STDEV.S(H2:H6)*100 -> 0.56500964
A3: =Tablica!N4/Tablica!G4 -> 0.0015772871 | B3: =Tablica!N10/Tablica!G10 -> 0.0079840319 | C3: =Tablica!N16/Tablica!G16 -> 0 | D3: =Tablica!N22/Tablica!G22 -> 0.0027497709 | E3: =Tablica!N28/Tablica!G28 -> 0.0045248869 | F3: =Tablica!N34/Tablica!G34 -> 0.0026525199 | G3: =Tablica!N40/Tablica!G40 -> 0 | H3: =Tablica!N46/Tablica!G46 -> 0.012131716
A4: =Tablica!N5/Tablica!G5 -> 0.0019011407 | B4: =Tablica!N11/Tablica!G11 -> 0.0040322581 | C4: =Tablica!N17/Tablica!G17 -> 0 | D4: =Tablica!N23/Tablica!G23 -> 0.0015337423 | E4: =Tablica!N29/Tablica!G29 -> 0 | F4: =Tablica!N35/Tablica!G35 -> 0 | G4: =Tablica!N41/Tablica!G41 -> 0 | H4: =Tablica!N47/Tablica!G47 -> 0.011787819
A5: =Tablica!N6/Tablica!G6 -> 0 | B5: =Tablica!N12/Tablica!G12 -> 0 | C5: =Tablica!N18/Tablica!G18 -> 0 | D5: =Tablica!N24/Tablica!G24 -> 0 | F5: =Tablica!N36/Tablica!G36 -> 0 | G5: =Tablica!N42/Tablica!G42 -> 0.0019083969 | H5: =Tablica!N48/Tablica!G48 -> 0.0019762846
A6: =Tablica!N7/Tablica!G7 -> 0 | C6: =Tablica!N19/Tablica!G19 -> 0.0066666667 | D6: =Tablica!N25/Tablica!G25 -> 0 | E6: =Tablica!N31/Tablica!G31 -> 0.014198783 | F6: =Tablica!N37/Tablica!G37 -> 0.011655012 | G6: =Tablica!N43/Tablica!G43 -> 0 | H6: =Tablica!N49/Tablica!G49 -> 0
A8: Anova: Single Factor
A10: SUMMARY
A11: Groups | B11: Count | C11: Sum | D11: Average | E11: Variance
A12: Column 1 | B12: 5 | C12: 0.0034784278 | D12: 0.00069568555 | E12: 9.2056962e-07
A13: Column 2 | B13: 4 | C13: 0.01401629 | D13: 0.0035040725 | E13: 1.1629925e-05
A14: Column 3 | B14: 5 | C14: 0.0066666667 | D14: 0.0013333333 | E14: 8.8888889e-06
A15: Column 4 | B15: 5 | C15: 0.0042835132 | D15: 0.00085670264 | E15: 1.5609771e-06
A16: Column 5 | B16: 4 | C16: 0.020484233 | D16: 0.0051210583 | E16: 4.009289e-05
A17: Column 6 | B17: 5 | C17: 0.019418264 | D17: 0.0038836528 | E17: 2.3395237e-05
A18: Column 7 | B18: 5 | C18: 0.0019083969 | D18: 0.00038167939 | E18: 7.2839578e-07
A19: Column 8 | B19: 5 | C19: 0.029794455 | D19: 0.005958891 | E19: 3.192359e-05
A22: ANOVA
A23: Source of Variation | B23: SS | C23: df | D23: MS | E23: F | F23: P-value | G23: F crit
A24: Between Groups | B24: 0.00015925521 | C24: 7 | D24: 2.2750744e-05 | E24: 1.6065432 | F24: 0.17183538 | G24: 2.334344
A25: Within Groups | B25: 0.00042483908 | C25: 30 | D25: 1.4161303e-05
A27: Total | B27: 0.00058409429 | C27: 37
A29: Group1 | B29: Group2 | C29: Statistic | D29: PValue | E29: CI_Low | F29: CI_High
A30: K- | B30: K+ | C30: -0.002808 | D30: 0.948963 | E30: -0.011022 | F30: 0.005405
A31: K- | B31: V1 | C31: -0.000638 | D31: 0.999994 | E31: -0.008382 | F31: 0.007106
A32: K- | B32: A1 | C32: -0.000161 | D32: 1 | E32: -0.007905 | F32: 0.007583
A33: K- | B33: U1 | C33: -0.004425 | D33: 0.65437 | E33: -0.012639 | F33: 0.003788
A34: K- | B34: V2 | C34: -0.003188 | D34: 0.876234 | E34: -0.010932 | F34: 0.004556
A35: K- | B35: A2 | C35: 0.000314 | D35: 1 | E35: -0.00743 | F35: 0.008058
A36: K- | B36: U2 | C36: -0.005263 | D36: 0.373519 | E36: -0.013007 | F36: 0.002481
A37: K+ | B37: V1 | C37: 0.002171 | D37: 0.987515 | E37: -0.006043 | F37: 0.010384
A38: K+ | B38: A1 | C38: 0.002647 | D38: 0.962435 | E38: -0.005566 | F38: 0.010861
A39: K+ | B39: U1 | C39: -0.001617 | D39: 0.998502 | E39: -0.010275 | F39: 0.007041
A40: K+ | B40: V2 | C40: -0.00038 | D40: 1 | E40: -0.008593 | F40: 0.007834
A41: K+ | B41: A2 | C41: 0.003122 | D41: 0.914048 | E41: -0.005091 | F41: 0.011336
... A57: A2 | B57: U2 | C57: -0.005577 | D57: 0.30458 | E57: -0.013321 | F57: 0.002167

Sheet Interfazne vakuole
A1: K- | B1: K+ | C1: V1 | D1: A1 | E1: U1 | F1: V2 | G1: A2 | H1: U2 | J1: K- | K1: K+ | L1: V1 | M1: A1 | N1: U1 | O1: V2 | P1: A2 | Q1: U2
A2: =Tablica!R3/Tablica!G3 -> 0.071047957 | B2: =Tablica!R9/Tablica!G9 -> 0.094 | C2: =Tablica!R15/Tablica!G15 -> 0.14039409 | D2: =Tablica!R21/Tablica!G21 -> 0.34153005 | E2: =Tablica!R27/Tablica!G27 -> 0.23943662 | F2: =Tablica!R33/Tablica!G33 -> 0.03407155 | G2: =Tablica!R39/Tablica!G39 -> 0.29330709 | H2: =Tablica!R45/Tablica!G45 -> 0.15594542 | J2: =_xlfn.STDEV.S(A2:A6)*100 -> 1.249805 | K2: =_xlfn.STDEV.S(B2:B6)*100 -> 4.4455744 | L2: =_xlfn.STDEV.S(C2:C6)*100 -> 8.8154767 | M2: =_xlfn.STDEV.S(D2:D6)*100 -> 17.463458 | N2: =_xlfn.STDEV.S(E2:E6)*100 -> 8.6463074 | O2: =_xlfn.STDEV.S(F2:F6)*100 -> 5.8380504 | P2: =_xlfn.STDEV.S(G2:G6)*100 -> 8.397061 | Q2: =_xlfn.STDEV.S(H2:H6)*100 -> 9.6103215
A3: =Tablica!R4/Tablica!G4 -> 0.072555205 | B3: =Tablica!R10/Tablica!G10 -> 0.053892216 | C3: =Tablica!R16/Tablica!G16 -> 0 | D3: =Tablica!R22/Tablica!G22 -> 0.19890009 | E3: =Tablica!R28/Tablica!G28 -> 0.031674208 | F3: =Tablica!R34/Tablica!G34 -> 0.16710875 | G3: =Tablica!R40/Tablica!G40 -> 0.12543554 | H3: =Tablica!R46/Tablica!G46 -> 0
A4: =Tablica!R5/Tablica!G5 -> 0.068441065 | B4: =Tablica!R11/Tablica!G11 -> 0.16129032 | C4: =Tablica!R17/Tablica!G17 -> 0.015779093 | D4: =Tablica!R23/Tablica!G23 -> 0.18404908 | E4: =Tablica!R29/Tablica!G29 -> 0.10181818 | F4: =Tablica!R35/Tablica!G35 -> 0.089403974 | G4: =Tablica!R41/Tablica!G41 -> 0.136 | H4: =Tablica!R47/Tablica!G47 -> 0.18860511
A5: =Tablica!R6/Tablica!G6 -> 0.057866184 | B5: =Tablica!R12/Tablica!G12 -> 0.11023622 | C5: =Tablica!R18/Tablica!G18 -> 0.13655462 | D5: =Tablica!R24/Tablica!G24 -> 0.011695906 | F5: =Tablica!R36/Tablica!G36 -> 0.086238532 | G5: =Tablica!R42/Tablica!G42 -> 0.25572519 | H5: =Tablica!R48/Tablica!G48 -> 0.17786561
A6: =Tablica!R7/Tablica!G7 -> 0.042654028 | C6: =Tablica!R19/Tablica!G19 -> 0.205 | D6: =Tablica!R25/Tablica!G25 -> 0.47400612 | E6: =Tablica!R31/Tablica!G31 -> 0.11359026 | F6: =Tablica!R37/Tablica!G37 -> 0.17016317 | G6: =Tablica!R43/Tablica!G43 -> 0.11066398 | H6: =Tablica!R49/Tablica!G49 -> 0
A8: Anova: Single Factor
A10: SUMMARY
A11: Groups | B11: Count | C11: Sum | D11: Average | E11: Variance
A12: Column 1 | B12: 5 | C12: 0.31256444 | D12: 0.062512888 | E12: 0.00015620124
A13: Column 2 | B13: 4 | C13: 0.41941876 | D13: 0.10485469 | E13: 0.0019763132
A14: Column 3 | B14: 5 | C14: 0.4977278 | D14: 0.099545561 | E14: 0.0077712629
A15: Column 4 | B15: 5 | C15: 1.2101812 | D15: 0.24203625 | E15: 0.030497237
A16: Column 5 | B16: 4 | C16: 0.48651927 | D16: 0.12162982 | E16: 0.0074758632
A17: Column 6 | B17: 5 | C17: 0.54698598 | D17: 0.1093972 | E17: 0.0034082833
A18: Column 7 | B18: 5 | C18: 0.9211318 | D18: 0.18422636 | E18: 0.0070510633
A19: Column 8 | B19: 5 | C19: 0.52241614 | D19: 0.10448323 | E19: 0.009235828
A22: ANOVA
A23: Source of Variation | B23: SS | C23: df | D23: MS | E23: F | F23: P-value | G23: F crit
A24: Between Groups | B24: 0.11304632 | C24: 7 | D24: 0.016149474 | E24: 1.8574283 | F24: 0.11253284 | G24: 2.334344
A25: Within Groups | B25: 0.26083603 | C25: 30 | D25: 0.0086945345
A27: Total | B27: 0.37388235 | C27: 37
A29: Group1 | B29: Group2 | C29: Statistic | D29: PValue | E29: CI_Low | F29: CI_High
A30: K- | B30: K+ | C30: -0.042342 | D30: 0.997045 | E30: -0.245861 | F30: 0.161178
A31: K- | B31: V1 | C31: -0.037033 | D31: 0.998155 | E31: -0.228913 | F31: 0.154847
A32: K- | B32: A1 | C32: -0.179523 | D32: 0.079779 | E32: -0.371403 | F32: 0.012357
A33: K- | B33: U1 | C33: -0.059117 | D33: 0.978642 | E33: -0.262636 | F33: 0.144402
A34: K- | B34: V2 | C34: -0.046884 | D34: 0.992125 | E34: -0.238764 | F34: 0.144996
A35: K- | B35: A2 | C35: -0.121713 | D35: 0.459205 | E35: -0.313593 | F35: 0.070166
A36: K- | B36: U2 | C36: -0.04197 | D36: 0.995971 | E36: -0.23385 | F36: 0.14991
A37: K+ | B37: V1 | C37: 0.005309 | D37: 1 | E37: -0.19821 | F37: 0.208829
A38: K+ | B38: A1 | C38: -0.137182 | D38: 0.383681 | E38: -0.340701 | F38: 0.066338
A39: K+ | B39: U1 | C39: -0.016775 | D39: 0.999996 | E39: -0.231303 | F39: 0.197753
A40: K+ | B40: V2 | C40: -0.004543 | D40: 1 | E40: -0.208062 | F40: 0.198977
A41: K+ | B41: A2 | C41: -0.079372 | D41: 0.903118 | E41: -0.282891 | F41: 0.124148
... A57: A2 | B57: U2 | C57: 0.079743 | D57: 0.870976 | E57: -0.112137 | F57: 0.271623
