Workbook

Sheet Tablica
A1: Oznaka lukovice | B1: n | C1: Duljina korjenčića (mm)
C2: Suma | D2: Prosjek | E2: SD
A3: K- a | C3: =SUM(raw!A2:B50) -> 5491.231 | D3: =AVERAGE(raw!A2:B50) -> 63.851523 | E3: =_xlfn.STDEV.S(raw!A2:B50) -> 18.555272
A4: K- b | B4: 34 | C4: =SUM(raw!C2:C35) -> 1269.062 | D4: =AVERAGE(raw!C2:C35) -> 37.325353 | E4: =_xlfn.STDEV.S(raw!C2:C35) -> 17.870434
A5: K- c | C5: =SUM(raw!D2:E51) -> 6989.994 | D5: =AVERAGE(raw!D2:E51) -> 84.216795 | E5: =_xlfn.STDEV.S(raw!D2:E51) -> 31.053438
A6: K- d | C6: =SUM(raw!F2:F25) -> 387.851 | D6: =AVERAGE(raw!F2:F25) -> 16.160458 | E6: =_xlfn.STDEV.S(raw!F2:F25) -> 6.8157427
A7: K- e | C7: =SUM(raw!G2:G13) -> 108.926 | D7: =AVERAGE(raw!G2:G13) -> 9.0771667 | E7: =_xlfn.STDEV.S(raw!G2:G13) -> 3.0971049
A8: K- | C8: =SUM(raw!A2:G51) -> 14247.064 | D8: =AVERAGE(raw!A2:G51) -> 59.611146 | E8: =_xlfn.STDEV.S(raw!A2:G51) -> 33.348879
A9: K+ a | C9: =SUM(raw!M2:M31) -> 816.749 | D9: =AVERAGE(raw!M2:M31) -> 27.224967 | E9: =_xlfn.STDEV.S(raw!M2:M31) -> 6.9969232
A10: K+ b | C10: =SUM(raw!N2:N21) -> 448.566 | D10: =AVERAGE(raw!N2:N21) -> 22.4283 | E10: =_xlfn.STDEV.S(raw!N2:N21) -> 3.8212997
A11: K+ c | C11: =SUM(raw!O2:O29) -> 1428.065 | D11: =AVERAGE(raw!O2:O29) -> 51.002321 | E11: =_xlfn.STDEV.S(raw!O2:O29) -> 12.599496
A12: K+ d | C12: =SUM(raw!P2:P4) -> 35.706 | D12: =AVERAGE(raw!P2:P4) -> 11.902 | E12: =_xlfn.STDEV.S(raw!P2:P4) -> 2.1126202
A13: K+ e | C13: =SUM(raw!Q2:Q3) -> 4.13 | D13: =AVERAGE(raw!Q2:Q3) -> 2.065 | E13: =_xlfn.STDEV.S(raw!Q2:Q3) -> 0.28425693
A14: K+ | C14: =SUM(raw!M2:Q31) -> 2733.216 | D14: =AVERAGE(raw!M2:Q31) -> 32.930313 | E14: =_xlfn.STDEV.S(raw!M2:Q31) -> 16.21178
A15: V1 a | C15: =SUM(raw!R2:R37) -> 900.447 | D15: =AVERAGE(raw!R2:R37) -> 25.012417 | E15: =_xlfn.STDEV.S(raw!R2:R37) -> 7.6300312
A16: V1 b | C16: =SUM(raw!S2:S6) -> 75.867 | D16: =AVERAGE(raw!S2:S6) -> 15.1734 | E16: =_xlfn.STDEV.S(raw!S2:S23) -> 3.0701046
A17: V1 c | C17: =SUM(raw!T2:T23) -> 570.778 | D17: =AVERAGE(raw!T2:T23) -> 25.944455 | E17: =_xlfn.STDEV.S(raw!T2:T23) -> 7.0133233
A18: V1 d | C18: =SUM(raw!U2:U41) -> 1012.307 | D18: =AVERAGE(raw!U2:U41) -> 25.307675 | E18: =_xlfn.STDEV.S(raw!U2:U41) -> 5.3176848
A19: V1 e | C19: =SUM(raw!V2:V11) -> 350.085 | D19: =AVERAGE(raw!V2:V11) -> 35.0085 | E19: =_xlfn.STDEV.S(raw!V2:V11) -> 11.947922
A20: V1 | C20: =SUM(raw!R2:V41) -> 2909.484 | D20: =AVERAGE(raw!R2:V41) -> 25.747646 | E20: =_xlfn.STDEV.S(raw!R2:V41) -> 7.8720815
A21: A1 a | C21: =SUM(raw!H2:H60) -> 1799.889 | D21: =AVERAGE(raw!H2:H60) -> 30.506593 | E21: =_xlfn.STDEV.S(raw!H2:H60) -> 14.552551
A22: A1 b | C22: =SUM(raw!I2:I57) -> 2017.376 | D22: =AVERAGE(raw!I2:I57) -> 36.024571 | E22: =_xlfn.STDEV.S(raw!I2:I57) -> 13.917155
A23: A1 c | C23: =SUM(raw!J2:J68) -> 3112.433 | D23: =AVERAGE(raw!J2:J68) -> 46.454224 | E23: =_xlfn.STDEV.S(raw!J2:J68) -> 14.845181
A24: A1 d | C24: =SUM(raw!K2:K42) -> 2830.893 | D24: =AVERAGE(raw!K2:K42) -> 69.046171 | E24: =_xlfn.STDEV.S(raw!K2:K42) -> 28.239278
A25: A1 e | C25: =SUM(raw!L2:L3) -> 73.151 | D25: =AVERAGE(raw!L2:L3) -> 36.5755 | E25: =_xlfn.STDEV.S(raw!L2:L3) -> 1.8434274
A26: A1 | C26: =SUM(raw!H2:L68) -> 9878.715 | D26: =AVERAGE(raw!H2:L68) -> 43.711128 | E26: =_xlfn.STDEV.S(raw!H2:L68) -> 22.101026
A27: U1 a | C27: =SUM(raw!W2:W43) -> 3108.599 | D27: =AVERAGE(raw!W2:W43) -> 74.014262 | E27: =_xlfn.STDEV.S(raw!W2:W43) -> 32.889359
A28: U1 b | C28: =SUM(raw!X2:X54) -> 2674.563 | D28: =AVERAGE(raw!X2:X54) -> 50.463453 | E28: =_xlfn.STDEV.S(raw!X2:X54) -> 14.977174
A29: U1 c | C29: =SUM(raw!Y2:Y20) -> 524.613 | D29: =AVERAGE(raw!X2:X54) -> 50.463453 | E29: =_xlfn.STDEV.S(raw!X2:X54) -> 14.977174
A30: U1 d | C30: =SUM(raw!Z2:Z9) -> 135.901 | D30: =AVERAGE(raw!Z2:Z9) -> 16.987625 | E30: =_xlfn.STDEV.S(raw!Z2:Z9) -> 4.6886427
A31: U1 e | C31: =SUM(raw!AA2:AA50) -> 3054.465 | D31: =AVERAGE(raw!AA2:AA50) -> 62.33602 | E31: =_xlfn.STDEV.S(raw!AA2:AA50) -> 18.25168
A32: U1 | C32: =SUM(raw!W2:AA54) -> 9498.141 | D32: =AVERAGE(raw!W2:AA54) -> 55.544684 | E32: =_xlfn.STDEV.S(raw!W2:AA54) -> 26.343862
A33: V2 a | C33: =SUM(raw!AB2:AB9) -> 158.502 | D33: =AVERAGE(raw!AB2:AB9) -> 19.81275 | E33: =_xlfn.STDEV.S(raw!AB2:AB9) -> 12.37613
A34: V2 b | C34: =SUM(raw!AC2:AC47) -> 1544.205 | D34: =AVERAGE(raw!AC2:AC47) -> 33.569674 | E34: =_xlfn.STDEV.S(raw!AC2:AC47) -> 7.6092857
A35: V2 c | C35: =SUM(raw!AD2:AD69) -> 2890.87 | D35: =AVERAGE(raw!AD2:AD69) -> 42.512794 | E35: =_xlfn.STDEV.S(raw!AD2:AD69) -> 12.844526
A36: V2 d | C36: =SUM(raw!AE2:AE56) -> 2956.863 | D36: =AVERAGE(raw!AE2:AE56) -> 53.761145 | E36: =_xlfn.STDEV.S(raw!AE2:AE56) -> 11.182416
A37: V2 e | C37: =SUM(raw!AF2:AF31) -> 1202.65 | D37: =AVERAGE(raw!AF2:AF31) -> 40.088333 | E37: =_xlfn.STDEV.S(raw!AF2:AF31) -> 8.1667045
A38: V2 | C38: =SUM(raw!AB2:AF69) -> 8753.09 | D38: =AVERAGE(raw!AB2:AF69) -> 42.285459 | E38: =_xlfn.STDEV.S(raw!AB2:AF69) -> 13.643184
A39: A2 a | C39: =SUM(raw!AG2:AG38) -> 1388.43 | D39: =AVERAGE(raw!AG2:AG38) -> 37.525135 | E39: =_xlfn.STDEV.S(raw!AG2:AG38) -> 13.118295
A40: A2 b | C40: =SUM(raw!AH2:AH19) -> 370.878 | D40: =AVERAGE(raw!AH2:AH19) -> 20.604333 | E40: =_xlfn.STDEV.S(raw!AH2:AH19) -> 2.6745959
...

Sheet ANOVA
A1: Anova: Single Factor
A3: SUMMARY
A4: Groups | B4: Count | C4: Sum | D4: Average | E4: Variance | F4: SD
A5: K- | B5: 239 | C5: 14247.064 | D5: 59.611146 | E5: 1112.1477 | F5: =SQRT(E5) -> 33.348879
A6: K+ | B6: 83 | C6: 2733.216 | D6: 32.930313 | E6: 262.82182 | F6: =SQRT(E6) -> 16.21178
A7: V1 | B7: 113 | C7: 2909.484 | D7: 25.747646 | E7: 61.969667 | F7: =SQRT(E7) -> 7.8720815
A8: A1 | B8: 226 | C8: 9878.715 | D8: 43.711128 | E8: 488.45534 | F8: =SQRT(E8) -> 22.101026
A9: U1 | B9: 171 | C9: 9498.141 | D9: 55.544684 | E9: 693.99909 | F9: =SQRT(E9) -> 26.343862
A10: V2 | B10: 207 | C10: 8753.09 | D10: 42.285459 | E10: 186.13646 | F10: =SQRT(E10) -> 13.643184
A11: A2 | B11: 209 | C11: 8737.055 | D11: 41.804091 | E11: 183.70228 | F11: =SQRT(E11) -> 13.553682
A12: U2 | B12: 95 | C12: 5729.716 | D12: 60.3128 | E12: 324.96053 | F12: =SQRT(E12) -> 18.026662
A15: ANOVA
A16: Source of Variation | B16: SS | C16: df | D16: MS | E16: F | F16: P-value | G16: F crit
A17: Between Groups | B17: 147189.15 | C17: 7 | D17: 21027.021 | E17: 44.687354 | F17: 5.2269402e-57 | G17: 2.0164259
A18: Within Groups | B18: 628165.93 | C18: 1335 | D18: 470.53627
A20: Total | B20: 775355.07 | C20: 1342

Sheet Turkey-Kramer
A1: Group1 | B1: Group2 | C1: Statistic | D1: PValue | E1: CI_Low | F1: CI_High
A2: K- | B2: K+ | C2: 26.680833 | D2: 0 | E2: 18.291113 | F2: 35.070553
A3: K- | B3: V1 | C3: 33.8635 | D3: 0 | E3: 26.345702 | F3: 41.381299
A4: K- | B4: A1 | C4: 15.900018 | D4: 0 | E4: 9.790164 | F4: 22.009872
A5: K- | B5: U1 | C5: 4.066462 | D5: 0.570775 | E5: -2.52911 | F5: 10.662034
A6: K- | B6: V2 | C6: 17.325688 | D6: 0 | E6: 11.073373 | F6: 23.578002
A7: K- | B7: A2 | C7: 17.807056 | D7: 0 | E7: 11.570792 | F7: 24.043319
A8: K- | B8: U2 | C8: -0.701654 | D8: 0.999995 | E8: -8.688402 | F8: 7.285095
A9: K+ | B9: V1 | C9: 7.182667 | D9: 0.299472 | E9: -2.336683 | F9: 16.702017
A10: K+ | B10: A1 | C10: -10.780815 | D10: 0.002847 | E10: -19.232504 | F10: -2.329126
A11: K+ | B11: U1 | C11: -22.614371 | D11: 0 | E11: -31.423588 | F11: -13.805154
A12: K+ | B12: V2 | C12: -9.355146 | D12: 0.020777 | E12: -17.910388 | F12: -0.799903
A13: K+ | B13: A2 | C13: -8.873778 | D13: 0.035207 | E13: -17.417296 | F13: -0.330259
... A29: A2 | B29: U2 | C29: -18.508709 | D29: 0 | E29: -26.656866 | F29: -10.360552

Sheet raw
A1: K-a | B1: K-a | C1: K-b | D1: K-c | E1: K-c | F1: K-d | G1: K-e | H1: A1 a | I1: A1 b | J1: A1 c | K1: A1 d | L1: A1 e | M1: K+ a | N1: K+ b | O1: K+ c | P1: K+ d | Q1: K+ e | R1: V1 a | S1: V1 b | T1: V1 c | U1: V1 d | V1: V1 e | W1: U1 a | X1: U1 b | Y1: U1 c | Z1: U1 d | AA1: U1 e | AB1: V2 a | AC1: V2 b | AD1: V2 c | AE1: V2 d | AF1: V2 e | AG1: A2 a | AH1: A2 b | AI1: A2 c | AJ1: A2 d | AK1: A2 e | AL1: U2 a | AM1: U2 b | AN1: U2 c | AO1: U2 d | AP1: U2 e
A2: 78.175 | B2: 68.49 | C2: 49 | D2: 70.775 | E2: 118.08 | F2: 22.399 | G2: 9.14 | H2: 29.988 | I2: 44.649 | J2: 41.227 | K2: 101.623 | L2: 35.272 | M2: 36.056 | N2: 29.976 | O2: 31.925 | P2: 12.792 | Q2: 2.266 | R2: 30.333 | S2: 20.023 | T2: 27.552 | U2: 23.461 | V2: 60.748 | W2: 51.829 | X2: 54.075 | Y2: 35.496 | Z2: 17.16 | AA2: 67.456 | AB2: 46.958 | AC2: 21.953 | AD2: 60.32 | AE2: 53.805 | AF2: 30.159 | AG2: 43.337 | AH2: 21.216 | AI2: 65.603 | AJ2: 65.175 | AK2: 50.421 | AL2: 77.997 | AM2: 24.976 | AN2: 85.114 | AO2: 70.906 | AP2: 26.523
A3: 24.058 | B3: 88.605 | C3: 39.85 | D3: 115.518 | E3: 115.793 | F3: 13.6 | G3: 5.253 | H3: 16.342 | I3: 62.333 | J3: 52.352 | K3: 91.857 | L3: 37.879 | M3: 30.662 | N3: 23.378 | O3: 31.306 | P3: 9.49 | Q3: 1.864 | R3: 42.602 | S3: 15.076 | T3: 16.903 | U3: 30.467 | V3: 21.17 | W3: 45.027 | X3: 70.222 | Y3: 33.747 | Z3: 16.604 | AA3: 73.176 | AB3: 21.42 | AC3: 46.232 | AD3: 48.922 | AE3: 42.679 | AF3: 46.94 | AG3: 46.593 | AH3: 19.313 | AI3: 73.797 | AJ3: 54.376 | AK3: 66.758 | AL3: 65.288 | AM3: 47.45 | AN3: 111.114 | AO3: 41.356 | AP3: 28.714
A4: 66.756 | B4: 84.045 | C4: 36.255 | D4: 43.081 | E4: 125.447 | F4: 18.656 | G4: 9.865 | H4: 18.495 | I4: 58.315 | J4: 60.86 | K4: 93.715 | M4: 30.525 | N4: 20.28 | O4: 53.06 | P4: 13.424 | R4: 36.659 | S4: 15.692 | T4: 23.574 | U4: 31.754 | V4: 43.223 | W4: 111.956 | X4: 57.797 | Y4: 24.62 | Z4: 15.57 | AA4: 73.324 | AB4: 23.053 | AC4: 24.286 | AD4: 45.645 | AE4: 47.599 | AF4: 36.882 | AG4: 30.843 | AH4: 20.751 | AI4: 44.422 | AJ4: 50.742 | AK4: 40.828 | AL4: 76.186 | AM4: 36.986 | AN4: 76.283 | AO4: 36.857 | AP4: 25.504
A5: 47.051 | B5: 83.944 | C5: 6.455 | D5: 21.211 | E5: 130.25 | F5: 23.464 | G5: 12 | H5: 8.743 | I5: 45.863 | J5: 30.231 | K5: 89.369 | M5: 35.35 | N5: 21.073 | O5: 55.144 | R5: 38.564 | S5: 12.453 | T5: 21.82 | U5: 28.33 | V5: 26.956 | W5: 58.714 | X5: 60.912 | Y5: 37.966 | Z5: 23.093 | AA5: 73.865 | AB5: 18.81 | AC5: 29.179 | AD5: 31.678 | AE5: 50.163 | AF5: 38.648 | AG5: 34.25 | AH5: 23.172 | AI5: 26.53 | AJ5: 39.657 | AK5: 50.694 | AL5: 74.939 | AM5: 19.471 | AN5: 66.979 | AO5: 39.713 | AP5: 23.401
A6: 61.943 | B6: 76.412 | C6: 45.43 | D6: 23.855 | E6: 75.116 | F6: 20.012 | G6: 7.549 | H6: 48.782 | I6: 32.178 | J6: 72.231 | K6: 95.023 | M6: 22.125 | N6: 21.297 | O6: 73.086 | R6: 29.74 | S6: 12.623 | T6: 40.323 | U6: 20.277 | V6: 30.044 | W6: 29.315 | X6: 59.538 | Y6: 24.984 | Z6: 7.504 | AA6: 66.838 | AB6: 15.141 | AC6: 42.45 | AD6: 55.111 | AE6: 49.628 | AF6: 54.482 | AG6: 42.049 | AH6: 26.977 | AI6: 42.386 | AJ6: 35.922 | AK6: 50.507 | AL6: 73.639 | AM6: 35.811 | AN6: 69.26 | AO6: 44.738
A7: 79.654 | B7: 78.29 | C7: 38.72 | D7: 34.611 | E7: 77.735 | F7: 8.382 | G7: 10.054 | H7: 38.85 | I7: 37.603 | J7: 47.752 | K7: 108.164 | M7: 33.847 | N7: 18.544 | O7: 82.92 | R7: 31.246 | T7: 31.376 | U7: 29.578 | V7: 30.027 | W7: 100.855 | X7: 53.377 | Y7: 34.016 | Z7: 16.857 | AA7: 60.715 | AB7: 14.338 | AC7: 25.936 | AD7: 50.169 | AE7: 57.933 | AF7: 47.958 | AG7: 48.748 | AH7: 20.6 | AI7: 51.724 | AJ7: 55.231 | AK7: 41.53 | AL7: 57.164 | AM7: 20.255 | AN7: 86.202 | AO7: 56.733
A8: 84.752 | B8: 69.558 | C8: 33.975 | D8: 37.431 | E8: 94.446 | F8: 18.108 | G8: 4.827 | H8: 63.127 | I8: 45.636 | J8: 68.694 | K8: 103.053 | M8: 25.905 | N8: 25.173 | O8: 35.395 | R8: 31.674 | T8: 27.184 | U8: 35.429 | V8: 44.353 | W8: 128.387 | X8: 32.585 | Y8: 24.635 | Z8: 17.183 | AA8: 67.23 | AB8: 14.5 | AC8: 23.334 | AD8: 49.797 | AE8: 56.915 | AF8: 28.94 | AG8: 40.551 | AH8: 24.376 | AI8: 27.222 | AJ8: 52.027 | AK8: 51.404 | AL8: 90.866 | AN8: 82.352 | AO8: 47.965
A9: 27.727 | B9: 31.542 | C9: 6.025 | D9: 42.124 | E9: 105.966 | F9: 12.022 | G9: 10.797 | H9: 46.057 | I9: 45.16 | J9: 31.181 | K9: 72.998 | M9: 22.38 | N9: 24.382 | O9: 53.959 | R9: 32.602 | T9: 36.339 | U9: 11.947 | V9: 24.701 | W9: 70.361 | X9: 36.707 | Y9: 22.996 | Z9: 21.93 | AA9: 81.597 | AB9: 4.282 | AC9: 34.75 | AD9: 57.425 | AE9: 49.582 | AF9: 25.152 | AG9: 21.605 | AH9: 21.384 | AI9: 41.587 | AJ9: 34.383 | AK9: 57.285 | AL9: 89.397 | AN9: 62.716 | AO9: 58.857
A10: 58.369 | B10: 83.205 | C10: 45.895 | D10: 32.541 | E10: 66.259 | F10: 9.813 | G10: 12.426 | H10: 57.606 | I10: 41.115 | J10: 42.078 | K10: 54.148 | M10: 18.831 | N10: 23.996 | O10: 51.565 | R10: 27.198 | T10: 39.225 | U10: 17.38 | V10: 29.2 | W10: 106.227 | X10: 68.376 | Y10: 45.621 | AA10: 48.784 | AC10: 40.03 | AD10: 60.434 | AE10: 68.234 | AF10: 53.293 | AG10: 37.893 | AH10: 17.283 | AI10: 19.142 | AJ10: 44.84 | AK10: 56.388 | AL10: 58.762 | AN10: 83.236 | AO10: 48.188
A11: 69.725 | B11: 80.128 | C11: 19.065 | D11: 31.649 | E11: 84.777 | F11: 16.553 | G11: 5.954 | H11: 33.491 | I11: 48.214 | J11: 26.584 | K11: 22.227 | M11: 18.142 | N11: 24.498 | O11: 51.723 | R11: 37.133 | T11: 15.315 | U11: 28.326 | V11: 39.663 | W11: 114 | X11: 76.911 | Y11: 19.894 | AA11: 86.472 | AC11: 35.365 | AD11: 74.322 | AE11: 65.97 | AF11: 50.87 | AG11: 50.524 | AH11: 19.574 | AI11: 31.826 | AJ11: 45.741 | AK11: 51.479 | AL11: 89.553 | AN11: 84.775 | AO11: 51.446
A12: 38.823 | B12: 65.823 | C12: 22.565 | D12: 32.644 | E12: 83.276 | F12: 8.122 | G12: 14.544 | H12: 15.969 | I12: 32.484 | J12: 39.726 | K12: 50.008 | M12: 26.926 | N12: 18.539 | O12: 47.715 | R12: 19.092 | T12: 22.442 | U12: 19.125 | W12: 41.621 | X12: 65.819 | Y12: 23.953 | AA12: 74.569 | AC12: 29.291 | AD12: 47.494 | AE12: 57.031 | AF12: 41.207 | AG12: 20.401 | AH12: 17.493 | AI12: 55.211 | AJ12: 53.637 | AK12: 49.568 | AL12: 57.135 | AN12: 76.878 | AO12: 52.751
A13: 54.039 | B13: 57.783 | C13: 29.635 | D13: 99.053 | E13: 105.903 | F13: 25.153 | G13: 6.517 | H13: 42.206 | I13: 35.289 | J13: 34.743 | K13: 47.274 | M13: 35.37 | N13: 16.609 | O13: 53.225 | R13: 19.278 | T13: 25.26 | U13: 14.304 | W13: 18.942 | X13: 35.756 | Y13: 32.511 | AA13: 65.577 | AC13: 29.971 | AD13: 32.061 | AE13: 48.501 | AF13: 43.842 | AG13: 31.763 | AH13: 18.161 | AI13: 40.933 | AJ13: 55.097 | AK13: 31.517 | AL13: 58.545 | AN13: 53.662 | AO13: 34.317
A14: 71.947 | B14: 75.345 | C14: 31.23 | D14: 98.06 | E14: 85.485 | F14: 6.579 | H14: 49.152 | I14: 43.28 | J14: 30.296 | K14: 45.998 | M14: 25.955 | N14: 19.395 | O14: 72.438 | R14: 27.227 | T14: 27.664 | U14: 21.578 | W14: 133.609 | X14: 34.748 | Y14: 36.756 | AA14: 65.877 | AC14: 31.197 | AD14: 41.491 | AE14: 45.617 | AF14: 48.342 | AG14: 24.661 | AH14: 18.856 | AI14: 45.378 | AJ14: 46.712 | AK14: 28.652 | AL14: 51.44 | AN14: 55.869
A15: 50.436 | B15: 74.618 | C15: 37.245 | D15: 90.725 | E15: 93.568 | F15: 19.847 | H15: 23.94 | I15: 48.211 | J15: 40.694 | K15: 42.373 | M15: 23.905 | N15: 19.397 | O15: 66.769 | R15: 18.282 | T15: 24.005 | U15: 24.549 | W15: 67.789 | X15: 27.153 | Y15: 19.427 | AA15: 50.228 | AC15: 21.189 | AD15: 46.092 | AE15: 71.043 | AF15: 46.265 | AG15: 39.271 | AH15: 19.786 | AI15: 47 | AJ15: 55.368 | AK15: 37.613 | AL15: 75.038 | AN15: 39.056
A16: 35.404 | B16: 35.585 | C16: 39.53 | D16: 37.146 | E16: 93.861 | F16: 14.27 | H16: 33.258 | I16: 46.256 | J16: 60.404 | K16: 76.3 | M16: 23.735 | N16: 25.064 | O16: 52.185 | R16: 21.973 | T16: 23.438 | U16: 28.472 | W16: 71.493 | X16: 41.645 | Y16: 23.584 | AA16: 93.156 | AC16: 40.027 | AD16: 41.925 | AE16: 50.201 | AF16: 54.798 | AG16: 33.445 | AH16: 22.069 | AI16: 36.398 | AJ16: 46.735 | AK16: 57.552 | AL16: 57.707 | AN16: 55.025
A17: 52.473 | B17: 70.511 | C17: 14.62 | D17: 31.795 | E17: 146.226 | F17: 19.43 | H17: 37.973 | I17: 16.508 | J17: 50.329 | K17: 86.979 | M17: 35.855 | N17: 29.071 | O17: 33.578 | R17: 18.109 | T17: 21.7 | U17: 22.084 | W17: 52.76 | X17: 50.838 | Y17: 29.119 | AA17: 69.101 | AC17: 33.022 | AD17: 52.402 | AE17: 67.803 | AF17: 44.803 | AG17: 43.265 | AH17: 22.249 | AI17: 35.618 | AJ17: 42.688 | AK17: 56.692 | AL17: 79.662 | AN17: 73.301
A18: 59.141 | B18: 63.105 | C18: 14.91 | D18: 39.621 | E18: 108.586 | F18: 4.675 | H18: 42.919 | I18: 37.394 | J18: 57.351 | K18: 51.753 | M18: 24.577 | N18: 24.025 | O18: 37.682 | R18: 15.926 | T18: 17.586 | U18: 30.945 | W18: 19.951 | X18: 52.041 | Y18: 20.695 | AA18: 45.483 | AC18: 38.766 | AD18: 57.232 | AE18: 45.533 | AF18: 29.081 | AG18: 41.787 | AH18: 21.524 | AI18: 34.258 | AJ18: 33.139 | AK18: 49.523 | AL18: 59.472 | AN18: 77.185
A19: 81.782 | B19: 78.849 | C19: 14.47 | D19: 88.802 | E19: 97.418 | F19: 10.028 | H19: 37.562 | I19: 11.648 | J19: 32.164 | K19: 81.255 | M19: 29.735 | N19: 24.672 | O19: 42.009 | R19: 20.202 | T19: 15.008 | U19: 23.593 | W19: 92.218 | X19: 50.424 | Y19: 18.363 | AA19: 36.585 | AC19: 45.955 | AD19: 47.089 | AE19: 25.744 | AF19: 37.306 | AG19: 44.102 | AH19: 16.094 | AI19: 35.541 | AJ19: 42.38 | AK19: 24.389 | AL19: 56.07 | AN19: 68.849
A20: 78.217 | B20: 72.534 | C20: 51.71 | D20: 75.955 | E20: 63.954 | F20: 25.507 | H20: 30.604 | I20: 34.288 | J20: 30.573 | K20: 65.744 | M20: 28.632 | N20: 23.877 | O20: 53.826 | R20: 17.954 | T20: 27.686 | U20: 33.788 | W20: 37.716 | X20: 17.511 | Y20: 16.23 | AA20: 37.478 | AC20: 27.978 | AD20: 51.305 | AE20: 35.262 | AF20: 33.878 | AG20: 35.167 | AI20: 24.577 | AJ20: 45.283 | AK20: 46.095 | AL20: 74.21 | AN20: 58.142
A21: 61.638 | B21: 87.44 | C21: 44.445 | D21: 40.399 | E21: 98.174 | F21: 27.946 | H21: 25.735 | I21: 47.674 | J21: 59.319 | K21: 53.317 | M21: 16.433 | N21: 15.32 | O21: 45.042 | R21: 23.513 | T21: 32.765 | U21: 26.79 | W21: 51.682 | X21: 50.057 | AA21: 33.423 | AC21: 37.188 | AD21: 30.082 | AE21: 28.997 | AF21: 35.527 | AG21: 39.995 | AI21: 53.458 | AJ21: 45.217 | AK21: 34.771 | AL21: 57.883 | AN21: 66.289
A22: 66.771 | B22: 34.1 | C22: 15.96 | D22: 97.725 | E22: 140.547 | F22: 24.372 | H22: 20.006 | I22: 54.31 | J22: 47.636 | K22: 16.262 | M22: 21.312 | O22: 54.108 | R22: 14.523 | T22: 25.002 | U22: 20.286 | W22: 46.995 | X22: 49.888 | AA22: 45.139 | AC22: 36.766 | AD22: 27.031 | AE22: 69.604 | AF22: 39.087 | AG22: 45.497 | AI22: 50.438 | AJ22: 57.268 | AK22: 38.801 | AL22: 65.417 | AN22: 66.43
A23: 73.876 | B23: 41.168 | C23: 42.665 | D23: 87.273 | E23: 77.309 | F23: 10.099 | H23: 24.231 | I23: 35.355 | J23: 49.771 | K23: 41.644 | M23: 47.493 | O23: 64.243 | R23: 15.79 | T23: 28.611 | U23: 31.659 | W23: 76.024 | X23: 40.465 | AA23: 60.947 | AC23: 35.564 | AD23: 61.678 | AE23: 56.277 | AF23: 37.668 | AG23: 33.462 | AI23: 34.569 | AJ23: 54.873 | AK23: 44.355 | AL23: 67.157 | AN23: 53.44
A24: 60.81 | B24: 71.7 | C24: 55.145 | D24: 42.215 | E24: 83.02 | F24: 9.141 | H24: 45.7 | I24: 30.658 | J24: 33.012 | K24: 57.159 | M24: 21.466 | O24: 39.87 | R24: 30.313 | U24: 24.925 | W24: 93.173 | X24: 71.358 | AA24: 58.484 | AC24: 26.577 | AD24: 48.904 | AE24: 50.476 | AF24: 42.664 | AG24: 48.476 | AI24: 45.501 | AJ24: 53.923 | AK24: 55.532 | AL24: 58.048 | AN24: 57.695
A25: 71.199 | B25: 76.286 | C25: 36.54 | D25: 103.037 | E25: 82.643 | F25: 19.673 | H25: 22.219 | I25: 38.073 | J25: 37.938 | K25: 106.99 | M25: 30.057 | O25: 43.839 | R25: 29.767 | U25: 30.678 | W25: 106.182 | X25: 51.681 | AA25: 43.338 | AC25: 35.719 | AD25: 24.346 | AE25: 30.552 | AF25: 39.576 | AG25: 96.529 | AI25: 34.004 | AJ25: 36.637 | AK25: 46.032 | AL25: 48.951 | AN25: 80.134
A26: 57.131 | B26: 45.753 | C26: 54.14 | D26: 83.296 | E26: 86.043 | H26: 44.54 | I26: 31.178 | J26: 28.408 | K26: 39.296 | M26: 26.301 | O26: 44.85 | R26: 15.026 | U26: 26.566 | W26: 38.665 | X26: 58.404 | AA26: 41.334 | AC26: 24.398 | AD26: 20.476 | AE26: 45.976 | AF26: 29.516 | AG26: 23.844 | AI26: 31.268 | AJ26: 33.439 | AK26: 36.332 | AL26: 48.062 | AN26: 98.663
A27: 50.156 | B27: 95.922 | C27: 102.21 | D27: 129.687 | E27: 100.703 | H27: 37.171 | I27: 29.952 | J27: 42.283 | K27: 96.685 | M27: 23.23 | O27: 54.451 | R27: 18.338 | U27: 29.462 | W27: 24.043 | X27: 44.334 | AA27: 52.138 | AC27: 25.427 | AD27: 40.356 | AE27: 51.62 | AF27: 45.257 | AG27: 34.5 | AI27: 48.41 | AJ27: 54.936 | AK27: 35.459 | AL27: 61.337 | AN27: 43.793
A28: 52.694 | B28: 84.021 | C28: 35.89 | D28: 56.555 | E28: 104.429 | H28: 20.486 | I28: 19.803 | J28: 39.826 | K28: 52.782 | M28: 17.188 | O28: 48.555 | R28: 34.713 | U28: 24.864 | W28: 87.952 | X28: 38.024 | AA28: 72.028 | AC28: 27.666 | AD28: 35.478 | AE28: 49.376 | AF28: 31.77 | AG28: 33.208 | AI28: 36.553 | AJ28: 63.977 | AK28: 52.869 | AL28: 68.024 | AN28: 45.597
A29: 92.837 | B29: 64.791 | C29: 48.79 | D29: 110.306 | E29: 64.45 | H29: 51.266 | I29: 39.407 | J29: 56.348 | K29: 18.363 | M29: 22.941 | O29: 53.597 | R29: 29.428 | U29: 18.686 | W29: 98.638 | X29: 19.115 | AA29: 71.79 | AC29: 28.029 | AD29: 43.842 | AE29: 50.824 | AF29: 30.749 | AG29: 34.598 | AI29: 38.824 | AJ29: 33.937 | AK29: 68.328 | AL29: 65.617 | AN29: 85.317
A30: 46.913 | B30: 66.103 | C30: 37.79 | D30: 133.215 | E30: 97.407 | H30: 37.619 | I30: 50.693 | J30: 77.786 | K30: 51.775 | M30: 25.543 | R30: 28.397 | U30: 27.418 | W30: 37.676 | X30: 69.645 | AA30: 97.26 | AC30: 28.538 | AD30: 47.475 | AE30: 52.976 | AF30: 36.802 | AG30: 47.678 | AI30: 27.797 | AJ30: 39.752 | AK30: 53.604 | AL30: 80.177 | AN30: 57.153
A31: 59.255 | B31: 69.024 | C31: 49.42 | D31: 102.11 | E31: 91.971 | H31: 8.075 | I31: 56.726 | J31: 57.784 | K31: 90.571 | M31: 36.272 | R31: 20.636 | U31: 29.191 | W31: 65.313 | X31: 89.572 | AA31: 66.185 | AC31: 52.078 | AD31: 35.811 | AE31: 51.421 | AF31: 41.188 | AG31: 40.533 | AI31: 33.748 | AJ31: 59.251 | AK31: 53.34 | AL31: 73.693 | AN31: 50.39
A32: 57.605 | B32: 83.229 | C32: 39.995 | D32: 36.732 | E32: 98.45 | H32: 22.544 | I32: 11.91 | J32: 51.789 | K32: 24.125 | R32: 23.457 | U32: 26.474 | W32: 63.756 | X32: 36.28 | AA32: 40.218 | AC32: 29.624 | AD32: 41.138 | AE32: 47.34 | AG32: 34.822 | AI32: 23.924 | AJ32: 26.621 | AK32: 61.65 | AL32: 55.938 | AN32: 55.632
A33: 55.567 | B33: 44.176 | C33: 47.475 | D33: 95.493 | E33: 35.01 | H33: 24.934 | I33: 52.008 | J33: 67.787 | K33: 47.609 | R33: 13.913 | U33: 26.333 | W33: 128.038 | X33: 28.866 | AA33: 66.266 | AC33: 41.433 | AD33: 24.075 | AE33: 59.118 | AG33: 28.405 | AI33: 26.4 | AJ33: 65.161 | AK33: 51.338 | AL33: 43.839 | AN33: 57.559
A34: 74.619 | B34: 28.968 | C34: 49.558 | D34: 127.732 | E34: 88.583 | H34: 39.705 | I34: 25.324 | J34: 63.937 | K34: 67.71 | R34: 22.287 | U34: 32.663 | W34: 102.517 | X34: 58.298 | AA34: 66.55 | AC34: 34.061 | AD34: 33.131 | AE34: 55.193 | AG34: 36.262 | AI34: 34.887 | AJ34: 60.763 | AK34: 62.073 | AL34: 61.27
A35: 33.633 | B35: 64.134 | C35: 32.454 | D35: 119.836 | H35: 57.265 | I35: 32.078 | J35: 64.764 | K35: 78.349 | R35: 18.682 | U35: 18.137 | W35: 102.924 | X35: 61.481 | AA35: 50.226 | AC35: 41.321 | AD35: 61.252 | AE35: 55.479 | AG35: 17.938 | AI35: 34.196 | AJ35: 52.915 | AK35: 60.63 | AL35: 67.618
A36: 55.387 | B36: 64.95 | D36: 45.843 | H36: 9.131 | I36: 45.911 | J36: 31.706 | K36: 99.171 | R36: 25.844 | U36: 24.29 | W36: 54.241 | X36: 73.37 | AA36: 79.353 | AC36: 35.555 | AD36: 37.479 | AE36: 57.088 | AG36: 32.115 | AI36: 31.17 | AJ36: 63.367 | AK36: 54.584 | AL36: 72.256
A37: 51.002 | B37: 81.54 | D37: 84.631 | H37: 4.487 | I37: 40.175 | J37: 30.85 | K37: 81.169 | R37: 20.026 | U37: 22.142 | W37: 120.795 | X37: 52.229 | AA37: 37.4 | AC37: 40.746 | AD37: 45.763 | AE37: 38.619 | AG37: 25.112 | AI37: 35.27 | AJ37: 42.997 | AK37: 50.197 | AL37: 47.098
A38: 25.815 | B38: 48.528 | D38: 34.172 | H38: 29.586 | I38: 27.802 | J38: 66.578 | K38: 24.201 | U38: 20.179 | W38: 105.049 | X38: 32.842 | AA38: 64.627 | AC38: 45.545 | AD38: 42.404 | AE38: 57.204 | AG38: 25.201 | AI38: 12.992 | AJ38: 62.198 | AK38: 43.584 | AL38: 76.565
A39: 67.709 | D39: 100.107 | H39: 31.828 | I39: 25.112 | J39: 28.676 | K39: 93.583 | U39: 25.44 | W39: 44.831 | X39: 49.825 | AA39: 68.476 | AC39: 45.479 | AD39: 48.957 | AE39: 50.075 | AI39: 14.913 | AJ39: 38.665 | AK39: 56.897 | AL39: 59.56
A40: 85.695 | D40: 97.458 | H40: 34.856 | I40: 64.69 | J40: 51.218 | K40: 101.878 | U40: 25.79 | W40: 35.992 | X40: 64.905 | AA40: 42.705 | AC40: 38.952 | AD40: 53.24 | AE40: 75.009 | AI40: 42.473 | AJ40: 57.091 | AK40: 46.524 | AL40: 46.459
...

Sheet raw2
A1: K- | B1: K+ | C1: V1 | D1: A1 | E1: U1 | F1: V2 | G1: A2 | H1: U2
A2: 78.175 | B2: 36.056 | C2: 30.333 | D2: 29.988 | E2: 51.829 | F2: 46.958 | G2: 43.337 | H2: 77.997
A3: 24.058 | B3: 30.662 | C3: 42.602 | D3: 16.342 | E3: 45.027 | F3: 21.42 | G3: 46.593 | H3: 65.288
A4: 66.756 | B4: 30.525 | C4: 36.659 | D4: 18.495 | E4: 111.956 | F4: 23.053 | G4: 30.843 | H4: 76.186
A5: 47.051 | B5: 35.35 | C5: 38.564 | D5: 8.743 | E5: 58.714 | F5: 18.81 | G5: 34.25 | H5: 74.939
A6: 61.943 | B6: 22.125 | C6: 29.74 | D6: 48.782 | E6: 29.315 | F6: 15.141 | G6: 42.049 | H6: 73.639
A7: 79.654 | B7: 33.847 | C7: 31.246 | D7: 38.85 | E7: 100.855 | F7: 14.338 | G7: 48.748 | H7: 57.164
A8: 84.752 | B8: 25.905 | C8: 31.674 | D8: 63.127 | E8: 128.387 | F8: 14.5 | G8: 40.551 | H8: 90.866
A9: 27.727 | B9: 22.38 | C9: 32.602 | D9: 46.057 | E9: 70.361 | F9: 4.282 | G9: 21.605 | H9: 89.397
A10: 58.369 | B10: 18.831 | C10: 27.198 | D10: 57.606 | E10: 106.227 | F10: 21.953 | G10: 37.893 | H10: 58.762
A11: 69.725 | B11: 18.142 | C11: 37.133 | D11: 33.491 | E11: 114 | F11: 46.232 | G11: 50.524 | H11: 89.553
A12: 38.823 | B12: 26.926 | C12: 19.092 | D12: 15.969 | E12: 41.621 | F12: 24.286 | G12: 20.401 | H12: 57.135
A13: 54.039 | B13: 35.37 | C13: 19.278 | D13: 42.206 | E13: 18.942 | F13: 29.179 | G13: 31.763 | H13: 58.545
... A84: 64.134 | B84: 1.864 | C84: 26.79 | D84: 38.073 | E84: 54.409 | F84: 47.475 | G84: 38.824 | H84: 39.713
A85: 64.95 | C85: 20.286 | D85: 31.178 | E85: 28.697 | F85: 35.811 | G85: 27.797 | H85: 44.738
A86: 81.54 | C86: 31.659 | D86: 29.952 | E86: 60.603 | F86: 41.138 | G86: 33.748 | H86: 56.733
A87: 48.528 | C87: 24.925 | D87: 19.803 | E87: 30.644 | F87: 24.075 | G87: 23.924 | H87: 47.965
A88: 49 | C88: 30.678 | D88: 39.407 | E88: 43.47 | F88: 33.131 | G88: 26.4 | H88: 58.857
A89: 39.85 | C89: 26.566 | D89: 50.693 | E89: 53.35 | F89: 61.252 | G89: 34.887 | H89: 48.188
A90: 36.255 | C90: 29.462 | D90: 56.726 | E90: 45.733 | F90: 37.479 | G90: 34.196 | H90: 51.446
A91: 6.455 | C91: 24.864 | D91: 11.91 | E91: 42.285 | F91: 45.763 | G91: 31.17 | H91: 52.751
A92: 45.43 | C92: 18.686 | D92: 52.008 | E92: 45.601 | F92: 42.404 | G92: 35.27 | H92: 34.317
A93: 38.72 | C93: 27.418 | D93: 25.324 | E93: 60.142 | F93: 48.957 | G93: 12.992 | H93: 26.523
A94: 33.975 | C94: 29.191 | D94: 32.078 | E94: 60.974 | F94: 53.24 | G94: 14.913 | H94: 28.714
A95: 6.025 | C95: 26.474 | D95: 45.911 | E95: 59.302 | F95: 64.826 | G95: 42.473 | H95: 25.504
A96: 45.895 | C96: 26.333 | D96: 40.175 | E96: 45.697 | F96: 41.156 | G96: 44.073 | H96: 23.401
A97: 19.065 | C97: 32.663 | D97: 27.802 | E97: 35.496 | F97: 35.755 | G97: 46.585
A98: 22.565 | C98: 18.137 | D98: 25.112 | E98: 33.747 | F98: 16.415 | G98: 43.717
A99: 29.635 | C99: 24.29 | D99: 64.69 | E99: 24.62 | F99: 29.402 | G99: 49.932
A100: 31.23 | C100: 22.142 | D100: 26.949 | E100: 37.966 | F100: 29.139 | G100: 23.068
A101: 37.245 | C101: 20.179 | D101: 52.396 | E101: 24.984 | F101: 54.084 | G101: 29.101
A102: 39.53 | C102: 25.44 | D102: 61.211 | E102: 34.016 | F102: 37.253 | G102: 44.294
A103: 14.62 | C103: 25.79 | D103: 41.104 | E103: 24.635 | F103: 44.117 | G103: 45.899
A104: 14.91 | C104: 24.947 | D104: 26.331 | E104: 22.996 | F104: 27.946 | G104: 47.143
A105: 14.47 | C105: 60.748 | D105: 29.303 | E105: 45.621 | F105: 53.452 | G105: 36.05
A106: 51.71 | C106: 21.17 | D106: 20.141 | E106: 19.894 | F106: 49.64 | G106: 44.88
A107: 44.445 | C107: 43.223 | D107: 20.682 | E107: 23.953 | F107: 42.141 | G107: 31.964
A108: 15.96 | C108: 26.956 | D108: 30.881 | E108: 32.511 | F108: 57.85 | G108: 55.915
... A114: 35.89 | C114: 39.663 | D114: 13.602 | E114: 18.363 | F114: 34.434 | G114: 50.742
A115: 48.79 | D115: 17.232 | E115: 16.23 | F115: 41.469 | G115: 39.657
...
